Workbook

Sheet الملخص
A1: ملخص مستحقات الجرد
A2: اكتب أي اسم جديد في عمود الاسم (أزرق) وسيُحسب تلقائيًا من شيت السجل
A3: الاسم | B3: جرد + مراجعة | C3: مراجعة فقط | D3: جرد فقط | E3: عدد الصيدليات | F3: إجمالي المستحق
A4: د. حسام شلش | B4: =IF(A4="","",COUNTIFS(السجل!$E$2:$E$1000,A4,السجل!$H$2:$H$1000,"جرد + مراجعة")) -> 19 | C4: =IF(A4="","",COUNTIFS(السجل!$E$2:$E$1000,A4,السجل!$H$2:$H$1000,"مراجعة فقط")) -> 18 | D4: =IF(A4="","",COUNTIFS(السجل!$E$2:$E$1000,A4,السجل!$H$2:$H$1000,"جرد فقط")) -> 0 | E4: =IF(A4="","",SUM(B4:D4)) -> 37 | F4: =IF(A4="","",SUMIFS(السجل!$I$2:$I$1000,السجل!$E$2:$E$1000,A4)) -> 6500
A5: د. السيد حسن | B5: =IF(A5="","",COUNTIFS(السجل!$E$2:$E$1000,A5,السجل!$H$2:$H$1000,"جرد + مراجعة")) -> 8 | C5: =IF(A5="","",COUNTIFS(السجل!$E$2:$E$1000,A5,السجل!$H$2:$H$1000,"مراجعة فقط")) -> 29 | D5: =IF(A5="","",COUNTIFS(السجل!$E$2:$E$1000,A5,السجل!$H$2:$H$1000,"جرد فقط")) -> 0 | E5: =IF(A5="","",SUM(B5:D5)) -> 37 | F5: =IF(A5="","",SUMIFS(السجل!$I$2:$I$1000,السجل!$E$2:$E$1000,A5)) -> 5950
A6: د. أيمن حسين | B6: =IF(A6="","",COUNTIFS(السجل!$E$2:$E$1000,A6,السجل!$H$2:$H$1000,"جرد + مراجعة")) -> 0 | C6: =IF(A6="","",COUNTIFS(السجل!$E$2:$E$1000,A6,السجل!$H$2:$H$1000,"مراجعة فقط")) -> 11 | D6: =IF(A6="","",COUNTIFS(السجل!$E$2:$E$1000,A6,السجل!$H$2:$H$1000,"جرد فقط")) -> 0 | E6: =IF(A6="","",SUM(B6:D6)) -> 11 | F6: =IF(A6="","",SUMIFS(السجل!$I$2:$I$1000,السجل!$E$2:$E$1000,A6)) -> 1650
A7: د. الحسن الغنيمي | B7: =IF(A7="","",COUNTIFS(السجل!$E$2:$E$1000,A7,السجل!$H$2:$H$1000,"جرد + مراجعة")) -> 0 | C7: =IF(A7="","",COUNTIFS(السجل!$E$2:$E$1000,A7,السجل!$H$2:$H$1000,"مراجعة فقط")) -> 23 | D7: =IF(A7="","",COUNTIFS(السجل!$E$2:$E$1000,A7,السجل!$H$2:$H$1000,"جرد فقط")) -> 0 | E7: =IF(A7="","",SUM(B7:D7)) -> 23 | F7: =IF(A7="","",SUMIFS(السجل!$I$2:$I$1000,السجل!$E$2:$E$1000,A7)) -> 3450
A8: د. علي خليفة | B8: =IF(A8="","",COUNTIFS(السجل!$E$2:$E$1000,A8,السجل!$H$2:$H$1000,"جرد + مراجعة")) -> 10 | C8: =IF(A8="","",COUNTIFS(السجل!$E$2:$E$1000,A8,السجل!$H$2:$H$1000,"مراجعة فقط")) -> 9 | D8: =IF(A8="","",COUNTIFS(السجل!$E$2:$E$1000,A8,السجل!$H$2:$H$1000,"جرد فقط")) -> 0 | E8: =IF(A8="","",SUM(B8:D8)) -> 19 | F8: =IF(A8="","",SUMIFS(السجل!$I$2:$I$1000,السجل!$E$2:$E$1000,A8)) -> 3350
A9: د. محمد جمال | B9: =IF(A9="","",COUNTIFS(السجل!$E$2:$E$1000,A9,السجل!$H$2:$H$1000,"جرد + مراجعة")) -> 0 | C9: =IF(A9="","",COUNTIFS(السجل!$E$2:$E$1000,A9,السجل!$H$2:$H$1000,"مراجعة فقط")) -> 18 | D9: =IF(A9="","",COUNTIFS(السجل!$E$2:$E$1000,A9,السجل!$H$2:$H$1000,"جرد فقط")) -> 0 | E9: =IF(A9="","",SUM(B9:D9)) -> 18 | F9: =IF(A9="","",SUMIFS(السجل!$I$2:$I$1000,السجل!$E$2:$E$1000,A9)) -> 2700
B10: =IF(A10="","",COUNTIFS(السجل!$E$2:$E$1000,A10,السجل!$H$2:$H$1000,"جرد + مراجعة")) | C10: =IF(A10="","",COUNTIFS(السجل!$E$2:$E$1000,A10,السجل!$H$2:$H$1000,"مراجعة فقط")) | D10: =IF(A10="","",COUNTIFS(السجل!$E$2:$E$1000,A10,السجل!$H$2:$H$1000,"جرد فقط")) | E10: =IF(A10="","",SUM(B10:D10)) | F10: =IF(A10="","",SUMIFS(السجل!$I$2:$I$1000,السجل!$E$2:$E$1000,A10))
B11: =IF(A11="","",COUNTIFS(السجل!$E$2:$E$1000,A11,السجل!$H$2:$H$1000,"جرد + مراجعة")) | C11: =IF(A11="","",COUNTIFS(السجل!$E$2:$E$1000,A11,السجل!$H$2:$H$1000,"مراجعة فقط")) | D11: =IF(A11="","",COUNTIFS(السجل!$E$2:$E$1000,A11,السجل!$H$2:$H$1000,"جرد فقط")) | E11: =IF(A11="","",SUM(B11:D11)) | F11: =IF(A11="","",SUMIFS(السجل!$I$2:$I$1000,السجل!$E$2:$E$1000,A11))
B12: =IF(A12="","",COUNTIFS(السجل!$E$2:$E$1000,A12,السجل!$H$2:$H$1000,"جرد + مراجعة")) | C12: =IF(A12="","",COUNTIFS(السجل!$E$2:$E$1000,A12,السجل!$H$2:$H$1000,"مراجعة فقط")) | D12: =IF(A12="","",COUNTIFS(السجل!$E$2:$E$1000,A12,السجل!$H$2:$H$1000,"جرد فقط")) | E12: =IF(A12="","",SUM(B12:D12)) | F12: =IF(A12="","",SUMIFS(السجل!$I$2:$I$1000,السجل!$E$2:$E$1000,A12))
B13: =IF(A13="","",COUNTIFS(السجل!$E$2:$E$1000,A13,السجل!$H$2:$H$1000,"جرد + مراجعة")) | C13: =IF(A13="","",COUNTIFS(السجل!$E$2:$E$1000,A13,السجل!$H$2:$H$1000,"مراجعة فقط")) | D13: =IF(A13="","",COUNTIFS(السجل!$E$2:$E$1000,A13,السجل!$H$2:$H$1000,"جرد فقط")) | E13: =IF(A13="","",SUM(B13:D13)) | F13: =IF(A13="","",SUMIFS(السجل!$I$2:$I$1000,السجل!$E$2:$E$1000,A13))
B14: =IF(A14="","",COUNTIFS(السجل!$E$2:$E$1000,A14,السجل!$H$2:$H$1000,"جرد + مراجعة")) | C14: =IF(A14="","",COUNTIFS(السجل!$E$2:$E$1000,A14,السجل!$H$2:$H$1000,"مراجعة فقط")) | D14: =IF(A14="","",COUNTIFS(السجل!$E$2:$E$1000,A14,السجل!$H$2:$H$1000,"جرد فقط")) | E14: =IF(A14="","",SUM(B14:D14)) | F14: =IF(A14="","",SUMIFS(السجل!$I$2:$I$1000,السجل!$E$2:$E$1000,A14))
B15: =IF(A15="","",COUNTIFS(السجل!$E$2:$E$1000,A15,السجل!$H$2:$H$1000,"جرد + مراجعة")) | C15: =IF(A15="","",COUNTIFS(السجل!$E$2:$E$1000,A15,السجل!$H$2:$H$1000,"مراجعة فقط")) | D15: =IF(A15="","",COUNTIFS(السجل!$E$2:$E$1000,A15,السجل!$H$2:$H$1000,"جرد فقط")) | E15: =IF(A15="","",SUM(B15:D15)) | F15: =IF(A15="","",SUMIFS(السجل!$I$2:$I$1000,السجل!$E$2:$E$1000,A15))
B16: =IF(A16="","",COUNTIFS(السجل!$E$2:$E$1000,A16,السجل!$H$2:$H$1000,"جرد + مراجعة")) | C16: =IF(A16="","",COUNTIFS(السجل!$E$2:$E$1000,A16,السجل!$H$2:$H$1000,"مراجعة فقط")) | D16: =IF(A16="","",COUNTIFS(السجل!$E$2:$E$1000,A16,السجل!$H$2:$H$1000,"جرد فقط")) | E16: =IF(A16="","",SUM(B16:D16)) | F16: =IF(A16="","",SUMIFS(السجل!$I$2:$I$1000,السجل!$E$2:$E$1000,A16))
B17: =IF(A17="","",COUNTIFS(السجل!$E$2:$E$1000,A17,السجل!$H$2:$H$1000,"جرد + مراجعة")) | C17: =IF(A17="","",COUNTIFS(السجل!$E$2:$E$1000,A17,السجل!$H$2:$H$1000,"مراجعة فقط")) | D17: =IF(A17="","",COUNTIFS(السجل!$E$2:$E$1000,A17,السجل!$H$2:$H$1000,"جرد فقط")) | E17: =IF(A17="","",SUM(B17:D17)) | F17: =IF(A17="","",SUMIFS(السجل!$I$2:$I$1000,السجل!$E$2:$E$1000,A17))
B18: =IF(A18="","",COUNTIFS(السجل!$E$2:$E$1000,A18,السجل!$H$2:$H$1000,"جرد + مراجعة")) | C18: =IF(A18="","",COUNTIFS(السجل!$E$2:$E$1000,A18,السجل!$H$2:$H$1000,"مراجعة فقط")) | D18: =IF(A18="","",COUNTIFS(السجل!$E$2:$E$1000,A18,السجل!$H$2:$H$1000,"جرد فقط")) | E18: =IF(A18="","",SUM(B18:D18)) | F18: =IF(A18="","",SUMIFS(السجل!$I$2:$I$1000,السجل!$E$2:$E$1000,A18))
A19: الإجمالي | B19: =SUM(B4:B18) -> 37 | C19: =SUM(C4:C18) -> 108 | D19: =SUM(D4:D18) -> 0 | E19: =SUM(E4:E18) -> 145 | F19: =SUM(F4:F18) -> 23600
A21: للتحقق: إجمالي السجل | F21: =SUM(السجل!$I$2:$I$1000) -> 23600

Sheet حسب اليوم
A1: الاسم | B1: الثلاثاء 2026-09-01 | C1: السبت 2026-09-26 | D1: الأحد 2026-09-27 | E1: الاثنين 2026-09-28 | F1: الثلاثاء 2026-09-29 | G1: الأربعاء 2026-09-30 | H1: الخميس 2026-10-01 | I1: الجمعة 2026-10-02 | J1: السبت 2026-10-03 | K1: الأحد 2026-10-04 | L1: الاثنين 2026-10-05 | M1: الثلاثاء 2026-10-06 | N1: الأربعاء 2026-10-07 | O1: الخميس 2026-10-08 | P1: الجمعة 2026-10-09 | Q1: السبت 2026-10-10 | R1: الأحد 2026-10-11 | S1: الثلاثاء 2026-10-13 | T1: الأربعاء 2026-10-14 | U1: الخميس 2026-10-15 | V1: الإجمالي
A2: =الملخص!A4 -> د. حسام شلش | B2: =SUMIFS(السجل!$I$2:$I$1000,السجل!$E$2:$E$1000,$A2,السجل!$A$2:$A$1000,B$1000) -> 400 | C2: =SUMIFS(السجل!$I$2:$I$1000,السجل!$E$2:$E$1000,$A2,السجل!$A$2:$A$1000,C$1000) -> 400 | D2: =SUMIFS(السجل!$I$2:$I$1000,السجل!$E$2:$E$1000,$A2,السجل!$A$2:$A$1000,D$1000) -> 300 | E2: =SUMIFS(السجل!$I$2:$I$1000,السجل!$E$2:$E$1000,$A2,السجل!$A$2:$A$1000,E$1000) -> 400 | F2: =SUMIFS(السجل!$I$2:$I$1000,السجل!$E$2:$E$1000,$A2,السجل!$A$2:$A$1000,F$1000) -> 300 | G2: =SUMIFS(السجل!$I$2:$I$1000,السجل!$E$2:$E$1000,$A2,السجل!$A$2:$A$1000,G$1000) -> 400 | H2: =SUMIFS(السجل!$I$2:$I$1000,السجل!$E$2:$E$1000,$A2,السجل!$A$2:$A$1000,H$1000) -> 150 | I2: =SUMIFS(السجل!$I$2:$I$1000,السجل!$E$2:$E$1000,$A2,السجل!$A$2:$A$1000,I$1000) -> 200 | ... U2: =SUMIFS(السجل!$I$2:$I$1000,السجل!$E$2:$E$1000,$A2,السجل!$A$2:$A$1000,U$1000) -> 300 | V2: =SUM(B2:U2) -> 6500
A3: =الملخص!A5 -> د. السيد حسن | B3: =SUMIFS(السجل!$I$2:$I$1000,السجل!$E$2:$E$1000,$A3,السجل!$A$2:$A$1000,B$1000) -> 300 | C3: =SUMIFS(السجل!$I$2:$I$1000,السجل!$E$2:$E$1000,$A3,السجل!$A$2:$A$1000,C$1000) -> 300 | D3: =SUMIFS(السجل!$I$2:$I$1000,السجل!$E$2:$E$1000,$A3,السجل!$A$2:$A$1000,D$1000) -> 300 | E3: =SUMIFS(السجل!$I$2:$I$1000,السجل!$E$2:$E$1000,$A3,السجل!$A$2:$A$1000,E$1000) -> 300 | F3: =SUMIFS(السجل!$I$2:$I$1000,السجل!$E$2:$E$1000,$A3,السجل!$A$2:$A$1000,F$1000) -> 300 | G3: =SUMIFS(السجل!$I$2:$I$1000,السجل!$E$2:$E$1000,$A3,السجل!$A$2:$A$1000,G$1000) -> 300 | H3: =SUMIFS(السجل!$I$2:$I$1000,السجل!$E$2:$E$1000,$A3,السجل!$A$2:$A$1000,H$1000) -> 150 | I3: =SUMIFS(السجل!$I$2:$I$1000,السجل!$E$2:$E$1000,$A3,السجل!$A$2:$A$1000,I$1000) -> 150 | ... U3: =SUMIFS(السجل!$I$2:$I$1000,السجل!$E$2:$E$1000,$A3,السجل!$A$2:$A$1000,U$1000) -> 300 | V3: =SUM(B3:U3) -> 5950
A4: =الملخص!A6 -> د. أيمن حسين | B4: =SUMIFS(السجل!$I$2:$I$1000,السجل!$E$2:$E$1000,$A4,السجل!$A$2:$A$1000,B$1000) -> 300 | C4: =SUMIFS(السجل!$I$2:$I$1000,السجل!$E$2:$E$1000,$A4,السجل!$A$2:$A$1000,C$1000) -> 0 | D4: =SUMIFS(السجل!$I$2:$I$1000,السجل!$E$2:$E$1000,$A4,السجل!$A$2:$A$1000,D$1000) -> 150 | E4: =SUMIFS(السجل!$I$2:$I$1000,السجل!$E$2:$E$1000,$A4,السجل!$A$2:$A$1000,E$1000) -> 150 | F4: =SUMIFS(السجل!$I$2:$I$1000,السجل!$E$2:$E$1000,$A4,السجل!$A$2:$A$1000,F$1000) -> 300 | G4: =SUMIFS(السجل!$I$2:$I$1000,السجل!$E$2:$E$1000,$A4,السجل!$A$2:$A$1000,G$1000) -> 300 | H4: =SUMIFS(السجل!$I$2:$I$1000,السجل!$E$2:$E$1000,$A4,السجل!$A$2:$A$1000,H$1000) -> 150 | I4: =SUMIFS(السجل!$I$2:$I$1000,السجل!$E$2:$E$1000,$A4,السجل!$A$2:$A$1000,I$1000) -> 150 | ... U4: =SUMIFS(السجل!$I$2:$I$1000,السجل!$E$2:$E$1000,$A4,السجل!$A$2:$A$1000,U$1000) -> 0 | V4: =SUM(B4:U4) -> 1650
A5: =الملخص!A7 -> د. الحسن الغنيمي | B5: =SUMIFS(السجل!$I$2:$I$1000,السجل!$E$2:$E$1000,$A5,السجل!$A$2:$A$1000,B$1000) -> 150 | C5: =SUMIFS(السجل!$I$2:$I$1000,السجل!$E$2:$E$1000,$A5,السجل!$A$2:$A$1000,C$1000) -> 0 | D5: =SUMIFS(السجل!$I$2:$I$1000,السجل!$E$2:$E$1000,$A5,السجل!$A$2:$A$1000,D$1000) -> 0 | E5: =SUMIFS(السجل!$I$2:$I$1000,السجل!$E$2:$E$1000,$A5,السجل!$A$2:$A$1000,E$1000) -> 0 | F5: =SUMIFS(السجل!$I$2:$I$1000,السجل!$E$2:$E$1000,$A5,السجل!$A$2:$A$1000,F$1000) -> 300 | G5: =SUMIFS(السجل!$I$2:$I$1000,السجل!$E$2:$E$1000,$A5,السجل!$A$2:$A$1000,G$1000) -> 150 | H5: =SUMIFS(السجل!$I$2:$I$1000,السجل!$E$2:$E$1000,$A5,السجل!$A$2:$A$1000,H$1000) -> 150 | I5: =SUMIFS(السجل!$I$2:$I$1000,السجل!$E$2:$E$1000,$A5,السجل!$A$2:$A$1000,I$1000) -> 150 | ... U5: =SUMIFS(السجل!$I$2:$I$1000,السجل!$E$2:$E$1000,$A5,السجل!$A$2:$A$1000,U$1000) -> 0 | V5: =SUM(B5:U5) -> 3450
A6: =الملخص!A8 -> د. علي خليفة | B6: =SUMIFS(السجل!$I$2:$I$1000,السجل!$E$2:$E$1000,$A6,السجل!$A$2:$A$1000,B$1000) -> 0 | C6: =SUMIFS(السجل!$I$2:$I$1000,السجل!$E$2:$E$1000,$A6,السجل!$A$2:$A$1000,C$1000) -> 300 | D6: =SUMIFS(السجل!$I$2:$I$1000,السجل!$E$2:$E$1000,$A6,السجل!$A$2:$A$1000,D$1000) -> 400 | E6: =SUMIFS(السجل!$I$2:$I$1000,السجل!$E$2:$E$1000,$A6,السجل!$A$2:$A$1000,E$1000) -> 300 | F6: =SUMIFS(السجل!$I$2:$I$1000,السجل!$E$2:$E$1000,$A6,السجل!$A$2:$A$1000,F$1000) -> 400 | G6: =SUMIFS(السجل!$I$2:$I$1000,السجل!$E$2:$E$1000,$A6,السجل!$A$2:$A$1000,G$1000) -> 300 | H6: =SUMIFS(السجل!$I$2:$I$1000,السجل!$E$2:$E$1000,$A6,السجل!$A$2:$A$1000,H$1000) -> 200 | I6: =SUMIFS(السجل!$I$2:$I$1000,السجل!$E$2:$E$1000,$A6,السجل!$A$2:$A$1000,I$1000) -> 150 | ... U6: =SUMIFS(السجل!$I$2:$I$1000,السجل!$E$2:$E$1000,$A6,السجل!$A$2:$A$1000,U$1000) -> 400 | V6: =SUM(B6:U6) -> 3350
A7: =الملخص!A9 -> د. محمد جمال | B7: =SUMIFS(السجل!$I$2:$I$1000,السجل!$E$2:$E$1000,$A7,السجل!$A$2:$A$1000,B$1000) -> 0 | C7: =SUMIFS(السجل!$I$2:$I$1000,السجل!$E$2:$E$1000,$A7,السجل!$A$2:$A$1000,C$1000) -> 0 | D7: =SUMIFS(السجل!$I$2:$I$1000,السجل!$E$2:$E$1000,$A7,السجل!$A$2:$A$1000,D$1000) -> 0 | E7: =SUMIFS(السجل!$I$2:$I$1000,السجل!$E$2:$E$1000,$A7,السجل!$A$2:$A$1000,E$1000) -> 0 | F7: =SUMIFS(السجل!$I$2:$I$1000,السجل!$E$2:$E$1000,$A7,السجل!$A$2:$A$1000,F$1000) -> 0 | G7: =SUMIFS(السجل!$I$2:$I$1000,السجل!$E$2:$E$1000,$A7,السجل!$A$2:$A$1000,G$1000) -> 0 | H7: =SUMIFS(السجل!$I$2:$I$1000,السجل!$E$2:$E$1000,$A7,السجل!$A$2:$A$1000,H$1000) -> 0 | I7: =SUMIFS(السجل!$I$2:$I$1000,السجل!$E$2:$E$1000,$A7,السجل!$A$2:$A$1000,I$1000) -> 0 | ... U7: =SUMIFS(السجل!$I$2:$I$1000,السجل!$E$2:$E$1000,$A7,السجل!$A$2:$A$1000,U$1000) -> 0 | V7: =SUM(B7:U7) -> 2700
A8: الإجمالي | B8: =SUM(B2:B7) -> 1150 | C8: =SUM(C2:C7) -> 1000 | D8: =SUM(D2:D7) -> 1150 | E8: =SUM(E2:E7) -> 1150 | F8: =SUM(F2:F7) -> 1600 | G8: =SUM(G2:G7) -> 1450 | H8: =SUM(H2:H7) -> 800 | I8: =SUM(I2:I7) -> 800 | ... V8: =SUM(V2:V7) -> 23600
B1000: 2026-09-01 | C1000: 2026-09-26 | D1000: 2026-09-27 | E1000: 2026-09-28 | F1000: 2026-09-29 | G1000: 2026-09-30 | H1000: 2026-10-01 | I1000: 2026-10-02 | J1000: 2026-10-03 | K1000: 2026-10-04 | L1000: 2026-10-05 | M1000: 2026-10-06 | N1000: 2026-10-07 | O1000: 2026-10-08 | P1000: 2026-10-09 | Q1000: 2026-10-10 | R1000: 2026-10-11 | S1000: 2026-10-13 | T1000: 2026-10-14 | U1000: 2026-10-15

Sheet الإعدادات
A1: البند | B1: المبلغ (ريال)
A2: جرد + مراجعة | B2: 200
A3: مراجعة فقط | B3: 150
A4: جرد فقط | B4: 100
A6: ملاحظات:
A7: • المستحق يُحسب لكل صيدلية: الشخص اللي جرد وراجع نفس الصيدلية = 200، راجع فقط = 150، جرد فقط = 100.
A8: • الخلايا الصفراء (باللون الأزرق) قابلة للتعديل، وكل الحسابات تتحدث تلقائيًا.
A9: • في شيت (السجل) كل صف = شخص واحد في صيدلية واحدة، واكتب (نعم) في عمود جرد و/أو راجع.

Sheet جدول الجرد
A1: اليوم | B1: التاريخ | C1: الصيدلية 1 | D1: الصيدلية 2 | E1: الموقع
A2: الثلاثاء | B2: 2026-09-01 | C2: صيدلية رقم 15 | D2: صيدلية رقم 16 | E2: الخرج
A3: السبت | B3: 2026-09-26 | C3: صيدلية رقم 4 | D3: صيدلية رقم 5 | E3: الخرج
A4: الأحد | B4: 2026-09-27 | C4: صيدلية رقم 3 | D4: صيدلية رقم 31 | E4: الخرج
A5: الاثنين | B5: 2026-09-28 | C5: صيدلية رقم 29 | D5: صيدلية رقم 22 | E5: الخرج
A6: الثلاثاء | B6: 2026-09-29 | C6: صيدلية رقم 21 | D6: صيدلية رقم 30 | E6: الخرج
A7: الأربعاء | B7: 2026-09-30 | C7: صيدلية رقم 10 | D7: صيدلية رقم 17 | E7: الخرج
A8: الخميس | B8: 2026-10-01 | C8: صيدلية رقم 28 | D8: *** | E8: الدلم
A9: الجمعة | B9: 2026-10-02 | C9: صيدلية رقم 7 | D9: *** | E9: الدلم
A10: السبت | B10: 2026-10-03 | C10: صيدلية رقم 9 | D10: *** | E10: الدلم
A11: الأحد | B11: 2026-10-04 | C11: صيدلية رقم 32 | D11: صيدلية رقم 39 | E11: الحوطة
A12: الاثنين | B12: 2026-10-05 | C12: صيدلية رقم 33 | D12: صيدلية رقم 34 | E12: الأفلاج
... A29: الجمعة | B29: 2026-10-23 | C29: صيدلية رقم 1 | D29: *** | E29: الخرج

Sheet السجل
A1: التاريخ | B1: اليوم | C1: الموقع | D1: رقم الصيدلية | E1: الاسم | F1: جرد | G1: راجع | H1: نوع المهمة | I1: المستحق
A2: 2026-09-01 | B2: =IF(A2="","",IFERROR(INDEX('جدول الجرد'!$A$2:$A$29,MATCH(A2,'جدول الجرد'!$B$2:$B$29,0)),"")) -> الثلاثاء | C2: =IF(A2="","",IFERROR(INDEX('جدول الجرد'!$E$2:$E$29,MATCH(A2,'جدول الجرد'!$B$2:$B$29,0)),"")) -> الخرج | D2: 15 | E2: د. حسام شلش | F2: نعم | G2: نعم | H2: =IF(E2="","",IF(AND(F2="نعم",G2="نعم"),"جرد + مراجعة",IF(F2="نعم","جرد فقط",IF(G2="نعم","مراجعة فقط","")))) -> جرد + مراجعة | I2: =IF(H2="جرد + مراجعة",الإعدادات!$B$2,IF(H2="مراجعة فقط",الإعدادات!$B$3,IF(H2="جرد فقط",الإعدادات!$B$4,0))) -> 200
A3: 2026-09-01 | B3: =IF(A3="","",IFERROR(INDEX('جدول الجرد'!$A$2:$A$29,MATCH(A3,'جدول الجرد'!$B$2:$B$29,0)),"")) -> الثلاثاء | C3: =IF(A3="","",IFERROR(INDEX('جدول الجرد'!$E$2:$E$29,MATCH(A3,'جدول الجرد'!$B$2:$B$29,0)),"")) -> الخرج | D3: 15 | E3: د. السيد حسن | G3: نعم | H3: =IF(E3="","",IF(AND(F3="نعم",G3="نعم"),"جرد + مراجعة",IF(F3="نعم","جرد فقط",IF(G3="نعم","مراجعة فقط","")))) -> مراجعة فقط | I3: =IF(H3="جرد + مراجعة",الإعدادات!$B$2,IF(H3="مراجعة فقط",الإعدادات!$B$3,IF(H3="جرد فقط",الإعدادات!$B$4,0))) -> 150
A4: 2026-09-01 | B4: =IF(A4="","",IFERROR(INDEX('جدول الجرد'!$A$2:$A$29,MATCH(A4,'جدول الجرد'!$B$2:$B$29,0)),"")) -> الثلاثاء | C4: =IF(A4="","",IFERROR(INDEX('جدول الجرد'!$E$2:$E$29,MATCH(A4,'جدول الجرد'!$B$2:$B$29,0)),"")) -> الخرج | D4: 15 | E4: د. أيمن حسين | G4: نعم | H4: =IF(E4="","",IF(AND(F4="نعم",G4="نعم"),"جرد + مراجعة",IF(F4="نعم","جرد فقط",IF(G4="نعم","مراجعة فقط","")))) -> مراجعة فقط | I4: =IF(H4="جرد + مراجعة",الإعدادات!$B$2,IF(H4="مراجعة فقط",الإعدادات!$B$3,IF(H4="جرد فقط",الإعدادات!$B$4,0))) -> 150
A5: 2026-09-01 | B5: =IF(A5="","",IFERROR(INDEX('جدول الجرد'!$A$2:$A$29,MATCH(A5,'جدول الجرد'!$B$2:$B$29,0)),"")) -> الثلاثاء | C5: =IF(A5="","",IFERROR(INDEX('جدول الجرد'!$E$2:$E$29,MATCH(A5,'جدول الجرد'!$B$2:$B$29,0)),"")) -> الخرج | D5: 16 | E5: د. حسام شلش | F5: نعم | G5: نعم | H5: =IF(E5="","",IF(AND(F5="نعم",G5="نعم"),"جرد + مراجعة",IF(F5="نعم","جرد فقط",IF(G5="نعم","مراجعة فقط","")))) -> جرد + مراجعة | I5: =IF(H5="جرد + مراجعة",الإعدادات!$B$2,IF(H5="مراجعة فقط",الإعدادات!$B$3,IF(H5="جرد فقط",الإعدادات!$B$4,0))) -> 200
A6: 2026-09-01 | B6: =IF(A6="","",IFERROR(INDEX('جدول الجرد'!$A$2:$A$29,MATCH(A6,'جدول الجرد'!$B$2:$B$29,0)),"")) -> الثلاثاء | C6: =IF(A6="","",IFERROR(INDEX('جدول الجرد'!$E$2:$E$29,MATCH(A6,'جدول الجرد'!$B$2:$B$29,0)),"")) -> الخرج | D6: 16 | E6: د. السيد حسن | G6: نعم | H6: =IF(E6="","",IF(AND(F6="نعم",G6="نعم"),"جرد + مراجعة",IF(F6="نعم","جرد فقط",IF(G6="نعم","مراجعة فقط","")))) -> مراجعة فقط | I6: =IF(H6="جرد + مراجعة",الإعدادات!$B$2,IF(H6="مراجعة فقط",الإعدادات!$B$3,IF(H6="جرد فقط",الإعدادات!$B$4,0))) -> 150
A7: 2026-09-01 | B7: =IF(A7="","",IFERROR(INDEX('جدول الجرد'!$A$2:$A$29,MATCH(A7,'جدول الجرد'!$B$2:$B$29,0)),"")) -> الثلاثاء | C7: =IF(A7="","",IFERROR(INDEX('جدول الجرد'!$E$2:$E$29,MATCH(A7,'جدول الجرد'!$B$2:$B$29,0)),"")) -> الخرج | D7: 16 | E7: د. أيمن حسين | G7: نعم | H7: =IF(E7="","",IF(AND(F7="نعم",G7="نعم"),"جرد + مراجعة",IF(F7="نعم","جرد فقط",IF(G7="نعم","مراجعة فقط","")))) -> مراجعة فقط | I7: =IF(H7="جرد + مراجعة",الإعدادات!$B$2,IF(H7="مراجعة فقط",الإعدادات!$B$3,IF(H7="جرد فقط",الإعدادات!$B$4,0))) -> 150
A8: 2026-09-01 | B8: =IF(A8="","",IFERROR(INDEX('جدول الجرد'!$A$2:$A$29,MATCH(A8,'جدول الجرد'!$B$2:$B$29,0)),"")) -> الثلاثاء | C8: =IF(A8="","",IFERROR(INDEX('جدول الجرد'!$E$2:$E$29,MATCH(A8,'جدول الجرد'!$B$2:$B$29,0)),"")) -> الخرج | D8: 16 | E8: د. الحسن الغنيمي | G8: نعم | H8: =IF(E8="","",IF(AND(F8="نعم",G8="نعم"),"جرد + مراجعة",IF(F8="نعم","جرد فقط",IF(G8="نعم","مراجعة فقط","")))) -> مراجعة فقط | I8: =IF(H8="جرد + مراجعة",الإعدادات!$B$2,IF(H8="مراجعة فقط",الإعدادات!$B$3,IF(H8="جرد فقط",الإعدادات!$B$4,0))) -> 150
A9: 2026-09-26 | B9: =IF(A9="","",IFERROR(INDEX('جدول الجرد'!$A$2:$A$29,MATCH(A9,'جدول الجرد'!$B$2:$B$29,0)),"")) -> السبت | C9: =IF(A9="","",IFERROR(INDEX('جدول الجرد'!$E$2:$E$29,MATCH(A9,'جدول الجرد'!$B$2:$B$29,0)),"")) -> الخرج | D9: 4 | E9: د. حسام شلش | F9: نعم | G9: نعم | H9: =IF(E9="","",IF(AND(F9="نعم",G9="نعم"),"جرد + مراجعة",IF(F9="نعم","جرد فقط",IF(G9="نعم","مراجعة فقط","")))) -> جرد + مراجعة | I9: =IF(H9="جرد + مراجعة",الإعدادات!$B$2,IF(H9="مراجعة فقط",الإعدادات!$B$3,IF(H9="جرد فقط",الإعدادات!$B$4,0))) -> 200
A10: 2026-09-26 | B10: =IF(A10="","",IFERROR(INDEX('جدول الجرد'!$A$2:$A$29,MATCH(A10,'جدول الجرد'!$B$2:$B$29,0)),"")) -> السبت | C10: =IF(A10="","",IFERROR(INDEX('جدول الجرد'!$E$2:$E$29,MATCH(A10,'جدول الجرد'!$B$2:$B$29,0)),"")) -> الخرج | D10: 4 | E10: د. السيد حسن | G10: نعم | H10: =IF(E10="","",IF(AND(F10="نعم",G10="نعم"),"جرد + مراجعة",IF(F10="نعم","جرد فقط",IF(G10="نعم","مراجعة فقط","")))) -> مراجعة فقط | I10: =IF(H10="جرد + مراجعة",الإعدادات!$B$2,IF(H10="مراجعة فقط",الإعدادات!$B$3,IF(H10="جرد فقط",الإعدادات!$B$4,0))) -> 150
A11: 2026-09-26 | B11: =IF(A11="","",IFERROR(INDEX('جدول الجرد'!$A$2:$A$29,MATCH(A11,'جدول الجرد'!$B$2:$B$29,0)),"")) -> السبت | C11: =IF(A11="","",IFERROR(INDEX('جدول الجرد'!$E$2:$E$29,MATCH(A11,'جدول الجرد'!$B$2:$B$29,0)),"")) -> الخرج | D11: 4 | E11: د. علي خليفة | G11: نعم | H11: =IF(E11="","",IF(AND(F11="نعم",G11="نعم"),"جرد + مراجعة",IF(F11="نعم","جرد فقط",IF(G11="نعم","مراجعة فقط","")))) -> مراجعة فقط | I11: =IF(H11="جرد + مراجعة",الإعدادات!$B$2,IF(H11="مراجعة فقط",الإعدادات!$B$3,IF(H11="جرد فقط",الإعدادات!$B$4,0))) -> 150
A12: 2026-09-26 | B12: =IF(A12="","",IFERROR(INDEX('جدول الجرد'!$A$2:$A$29,MATCH(A12,'جدول الجرد'!$B$2:$B$29,0)),"")) -> السبت | C12: =IF(A12="","",IFERROR(INDEX('جدول الجرد'!$E$2:$E$29,MATCH(A12,'جدول الجرد'!$B$2:$B$29,0)),"")) -> الخرج | D12: 5 | E12: د. حسام شلش | F12: نعم | G12: نعم | H12: =IF(E12="","",IF(AND(F12="نعم",G12="نعم"),"جرد + مراجعة",IF(F12="نعم","جرد فقط",IF(G12="نعم","مراجعة فقط","")))) -> جرد + مراجعة | I12: =IF(H12="جرد + مراجعة",الإعدادات!$B$2,IF(H12="مراجعة فقط",الإعدادات!$B$3,IF(H12="جرد فقط",الإعدادات!$B$4,0))) -> 200
A13: 2026-09-26 | B13: =IF(A13="","",IFERROR(INDEX('جدول الجرد'!$A$2:$A$29,MATCH(A13,'جدول الجرد'!$B$2:$B$29,0)),"")) -> السبت | C13: =IF(A13="","",IFERROR(INDEX('جدول الجرد'!$E$2:$E$29,MATCH(A13,'جدول الجرد'!$B$2:$B$29,0)),"")) -> الخرج | D13: 5 | E13: د. السيد حسن | G13: نعم | H13: =IF(E13="","",IF(AND(F13="نعم",G13="نعم"),"جرد + مراجعة",IF(F13="نعم","جرد فقط",IF(G13="نعم","مراجعة فقط","")))) -> مراجعة فقط | I13: =IF(H13="جرد + مراجعة",الإعدادات!$B$2,IF(H13="مراجعة فقط",الإعدادات!$B$3,IF(H13="جرد فقط",الإعدادات!$B$4,0))) -> 150
A14: 2026-09-26 | B14: =IF(A14="","",IFERROR(INDEX('جدول الجرد'!$A$2:$A$29,MATCH(A14,'جدول الجرد'!$B$2:$B$29,0)),"")) -> السبت | C14: =IF(A14="","",IFERROR(INDEX('جدول الجرد'!$E$2:$E$29,MATCH(A14,'جدول الجرد'!$B$2:$B$29,0)),"")) -> الخرج | D14: 5 | E14: د. علي خليفة | G14: نعم | H14: =IF(E14="","",IF(AND(F14="نعم",G14="نعم"),"جرد + مراجعة",IF(F14="نعم","جرد فقط",IF(G14="نعم","مراجعة فقط","")))) -> مراجعة فقط | I14: =IF(H14="جرد + مراجعة",الإعدادات!$B$2,IF(H14="مراجعة فقط",الإعدادات!$B$3,IF(H14="جرد فقط",الإعدادات!$B$4,0))) -> 150
A15: 2026-09-27 | B15: =IF(A15="","",IFERROR(INDEX('جدول الجرد'!$A$2:$A$29,MATCH(A15,'جدول الجرد'!$B$2:$B$29,0)),"")) -> الأحد | C15: =IF(A15="","",IFERROR(INDEX('جدول الجرد'!$E$2:$E$29,MATCH(A15,'جدول الجرد'!$B$2:$B$29,0)),"")) -> الخرج | D15: 3 | E15: د. علي خليفة | F15: نعم | G15: نعم | H15: =IF(E15="","",IF(AND(F15="نعم",G15="نعم"),"جرد + مراجعة",IF(F15="نعم","جرد فقط",IF(G15="نعم","مراجعة فقط","")))) -> جرد + مراجعة | I15: =IF(H15="جرد + مراجعة",الإعدادات!$B$2,IF(H15="مراجعة فقط",الإعدادات!$B$3,IF(H15="جرد فقط",الإعدادات!$B$4,0))) -> 200
A16: 2026-09-27 | B16: =IF(A16="","",IFERROR(INDEX('جدول الجرد'!$A$2:$A$29,MATCH(A16,'جدول الجرد'!$B$2:$B$29,0)),"")) -> الأحد | C16: =IF(A16="","",IFERROR(INDEX('جدول الجرد'!$E$2:$E$29,MATCH(A16,'جدول الجرد'!$B$2:$B$29,0)),"")) -> الخرج | D16: 3 | E16: د. حسام شلش | G16: نعم | H16: =IF(E16="","",IF(AND(F16="نعم",G16="نعم"),"جرد + مراجعة",IF(F16="نعم","جرد فقط",IF(G16="نعم","مراجعة فقط","")))) -> مراجعة فقط | I16: =IF(H16="جرد + مراجعة",الإعدادات!$B$2,IF(H16="مراجعة فقط",الإعدادات!$B$3,IF(H16="جرد فقط",الإعدادات!$B$4,0))) -> 150
A17: 2026-09-27 | B17: =IF(A17="","",IFERROR(INDEX('جدول الجرد'!$A$2:$A$29,MATCH(A17,'جدول الجرد'!$B$2:$B$29,0)),"")) -> الأحد | C17: =IF(A17="","",IFERROR(INDEX('جدول الجرد'!$E$2:$E$29,MATCH(A17,'جدول الجرد'!$B$2:$B$29,0)),"")) -> الخرج | D17: 3 | E17: د. السيد حسن | G17: نعم | H17: =IF(E17="","",IF(AND(F17="نعم",G17="نعم"),"جرد + مراجعة",IF(F17="نعم","جرد فقط",IF(G17="نعم","مراجعة فقط","")))) -> مراجعة فقط | I17: =IF(H17="جرد + مراجعة",الإعدادات!$B$2,IF(H17="مراجعة فقط",الإعدادات!$B$3,IF(H17="جرد فقط",الإعدادات!$B$4,0))) -> 150
A18: 2026-09-27 | B18: =IF(A18="","",IFERROR(INDEX('جدول الجرد'!$A$2:$A$29,MATCH(A18,'جدول الجرد'!$B$2:$B$29,0)),"")) -> الأحد | C18: =IF(A18="","",IFERROR(INDEX('جدول الجرد'!$E$2:$E$29,MATCH(A18,'جدول الجرد'!$B$2:$B$29,0)),"")) -> الخرج | D18: 31 | E18: د. علي خليفة | F18: نعم | G18: نعم | H18: =IF(E18="","",IF(AND(F18="نعم",G18="نعم"),"جرد + مراجعة",IF(F18="نعم","جرد فقط",IF(G18="نعم","مراجعة فقط","")))) -> جرد + مراجعة | I18: =IF(H18="جرد + مراجعة",الإعدادات!$B$2,IF(H18="مراجعة فقط",الإعدادات!$B$3,IF(H18="جرد فقط",الإعدادات!$B$4,0))) -> 200
A19: 2026-09-27 | B19: =IF(A19="","",IFERROR(INDEX('جدول الجرد'!$A$2:$A$29,MATCH(A19,'جدول الجرد'!$B$2:$B$29,0)),"")) -> الأحد | C19: =IF(A19="","",IFERROR(INDEX('جدول الجرد'!$E$2:$E$29,MATCH(A19,'جدول الجرد'!$B$2:$B$29,0)),"")) -> الخرج | D19: 31 | E19: د. حسام شلش | G19: نعم | H19: =IF(E19="","",IF(AND(F19="نعم",G19="نعم"),"جرد + مراجعة",IF(F19="نعم","جرد فقط",IF(G19="نعم","مراجعة فقط","")))) -> مراجعة فقط | I19: =IF(H19="جرد + مراجعة",الإعدادات!$B$2,IF(H19="مراجعة فقط",الإعدادات!$B$3,IF(H19="جرد فقط",الإعدادات!$B$4,0))) -> 150
A20: 2026-09-27 | B20: =IF(A20="","",IFERROR(INDEX('جدول الجرد'!$A$2:$A$29,MATCH(A20,'جدول الجرد'!$B$2:$B$29,0)),"")) -> الأحد | C20: =IF(A20="","",IFERROR(INDEX('جدول الجرد'!$E$2:$E$29,MATCH(A20,'جدول الجرد'!$B$2:$B$29,0)),"")) -> الخرج | D20: 31 | E20: د. السيد حسن | G20: نعم | H20: =IF(E20="","",IF(AND(F20="نعم",G20="نعم"),"جرد + مراجعة",IF(F20="نعم","جرد فقط",IF(G20="نعم","مراجعة فقط","")))) -> مراجعة فقط | I20: =IF(H20="جرد + مراجعة",الإعدادات!$B$2,IF(H20="مراجعة فقط",الإعدادات!$B$3,IF(H20="جرد فقط",الإعدادات!$B$4,0))) -> 150
A21: 2026-09-27 | B21: =IF(A21="","",IFERROR(INDEX('جدول الجرد'!$A$2:$A$29,MATCH(A21,'جدول الجرد'!$B$2:$B$29,0)),"")) -> الأحد | C21: =IF(A21="","",IFERROR(INDEX('جدول الجرد'!$E$2:$E$29,MATCH(A21,'جدول الجرد'!$B$2:$B$29,0)),"")) -> الخرج | D21: 31 | E21: د. أيمن حسين | G21: نعم | H21: =IF(E21="","",IF(AND(F21="نعم",G21="نعم"),"جرد + مراجعة",IF(F21="نعم","جرد فقط",IF(G21="نعم","مراجعة فقط","")))) -> مراجعة فقط | I21: =IF(H21="جرد + مراجعة",الإعدادات!$B$2,IF(H21="مراجعة فقط",الإعدادات!$B$3,IF(H21="جرد فقط",الإعدادات!$B$4,0))) -> 150
A22: 2026-09-28 | B22: =IF(A22="","",IFERROR(INDEX('جدول الجرد'!$A$2:$A$29,MATCH(A22,'جدول الجرد'!$B$2:$B$29,0)),"")) -> الاثنين | C22: =IF(A22="","",IFERROR(INDEX('جدول الجرد'!$E$2:$E$29,MATCH(A22,'جدول الجرد'!$B$2:$B$29,0)),"")) -> الخرج | D22: 29 | E22: د. حسام شلش | F22: نعم | G22: نعم | H22: =IF(E22="","",IF(AND(F22="نعم",G22="نعم"),"جرد + مراجعة",IF(F22="نعم","جرد فقط",IF(G22="نعم","مراجعة فقط","")))) -> جرد + مراجعة | I22: =IF(H22="جرد + مراجعة",الإعدادات!$B$2,IF(H22="مراجعة فقط",الإعدادات!$B$3,IF(H22="جرد فقط",الإعدادات!$B$4,0))) -> 200
A23: 2026-09-28 | B23: =IF(A23="","",IFERROR(INDEX('جدول الجرد'!$A$2:$A$29,MATCH(A23,'جدول الجرد'!$B$2:$B$29,0)),"")) -> الاثنين | C23: =IF(A23="","",IFERROR(INDEX('جدول الجرد'!$E$2:$E$29,MATCH(A23,'جدول الجرد'!$B$2:$B$29,0)),"")) -> الخرج | D23: 29 | E23: د. السيد حسن | G23: نعم | H23: =IF(E23="","",IF(AND(F23="نعم",G23="نعم"),"جرد + مراجعة",IF(F23="نعم","جرد فقط",IF(G23="نعم","مراجعة فقط","")))) -> مراجعة فقط | I23: =IF(H23="جرد + مراجعة",الإعدادات!$B$2,IF(H23="مراجعة فقط",الإعدادات!$B$3,IF(H23="جرد فقط",الإعدادات!$B$4,0))) -> 150
A24: 2026-09-28 | B24: =IF(A24="","",IFERROR(INDEX('جدول الجرد'!$A$2:$A$29,MATCH(A24,'جدول الجرد'!$B$2:$B$29,0)),"")) -> الاثنين | C24: =IF(A24="","",IFERROR(INDEX('جدول الجرد'!$E$2:$E$29,MATCH(A24,'جدول الجرد'!$B$2:$B$29,0)),"")) -> الخرج | D24: 29 | E24: د. علي خليفة | G24: نعم | H24: =IF(E24="","",IF(AND(F24="نعم",G24="نعم"),"جرد + مراجعة",IF(F24="نعم","جرد فقط",IF(G24="نعم","مراجعة فقط","")))) -> مراجعة فقط | I24: =IF(H24="جرد + مراجعة",الإعدادات!$B$2,IF(H24="مراجعة فقط",الإعدادات!$B$3,IF(H24="جرد فقط",الإعدادات!$B$4,0))) -> 150
A25: 2026-09-28 | B25: =IF(A25="","",IFERROR(INDEX('جدول الجرد'!$A$2:$A$29,MATCH(A25,'جدول الجرد'!$B$2:$B$29,0)),"")) -> الاثنين | C25: =IF(A25="","",IFERROR(INDEX('جدول الجرد'!$E$2:$E$29,MATCH(A25,'جدول الجرد'!$B$2:$B$29,0)),"")) -> الخرج | D25: 29 | E25: د. أيمن حسين | G25: نعم | H25: =IF(E25="","",IF(AND(F25="نعم",G25="نعم"),"جرد + مراجعة",IF(F25="نعم","جرد فقط",IF(G25="نعم","مراجعة فقط","")))) -> مراجعة فقط | I25: =IF(H25="جرد + مراجعة",الإعدادات!$B$2,IF(H25="مراجعة فقط",الإعدادات!$B$3,IF(H25="جرد فقط",الإعدادات!$B$4,0))) -> 150
A26: 2026-09-28 | B26: =IF(A26="","",IFERROR(INDEX('جدول الجرد'!$A$2:$A$29,MATCH(A26,'جدول الجرد'!$B$2:$B$29,0)),"")) -> الاثنين | C26: =IF(A26="","",IFERROR(INDEX('جدول الجرد'!$E$2:$E$29,MATCH(A26,'جدول الجرد'!$B$2:$B$29,0)),"")) -> الخرج | D26: 22 | E26: د. حسام شلش | F26: نعم | G26: نعم | H26: =IF(E26="","",IF(AND(F26="نعم",G26="نعم"),"جرد + مراجعة",IF(F26="نعم","جرد فقط",IF(G26="نعم","مراجعة فقط","")))) -> جرد + مراجعة | I26: =IF(H26="جرد + مراجعة",الإعدادات!$B$2,IF(H26="مراجعة فقط",الإعدادات!$B$3,IF(H26="جرد فقط",الإعدادات!$B$4,0))) -> 200
A27: 2026-09-28 | B27: =IF(A27="","",IFERROR(INDEX('جدول الجرد'!$A$2:$A$29,MATCH(A27,'جدول الجرد'!$B$2:$B$29,0)),"")) -> الاثنين | C27: =IF(A27="","",IFERROR(INDEX('جدول الجرد'!$E$2:$E$29,MATCH(A27,'جدول الجرد'!$B$2:$B$29,0)),"")) -> الخرج | D27: 22 | E27: د. السيد حسن | G27: نعم | H27: =IF(E27="","",IF(AND(F27="نعم",G27="نعم"),"جرد + مراجعة",IF(F27="نعم","جرد فقط",IF(G27="نعم","مراجعة فقط","")))) -> مراجعة فقط | I27: =IF(H27="جرد + مراجعة",الإعدادات!$B$2,IF(H27="مراجعة فقط",الإعدادات!$B$3,IF(H27="جرد فقط",الإعدادات!$B$4,0))) -> 150
A28: 2026-09-28 | B28: =IF(A28="","",IFERROR(INDEX('جدول الجرد'!$A$2:$A$29,MATCH(A28,'جدول الجرد'!$B$2:$B$29,0)),"")) -> الاثنين | C28: =IF(A28="","",IFERROR(INDEX('جدول الجرد'!$E$2:$E$29,MATCH(A28,'جدول الجرد'!$B$2:$B$29,0)),"")) -> الخرج | D28: 22 | E28: د. علي خليفة | G28: نعم | H28: =IF(E28="","",IF(AND(F28="نعم",G28="نعم"),"جرد + مراجعة",IF(F28="نعم","جرد فقط",IF(G28="نعم","مراجعة فقط","")))) -> مراجعة فقط | I28: =IF(H28="جرد + مراجعة",الإعدادات!$B$2,IF(H28="مراجعة فقط",الإعدادات!$B$3,IF(H28="جرد فقط",الإعدادات!$B$4,0))) -> 150
A29: 2026-09-29 | B29: =IF(A29="","",IFERROR(INDEX('جدول الجرد'!$A$2:$A$29,MATCH(A29,'جدول الجرد'!$B$2:$B$29,0)),"")) -> الثلاثاء | C29: =IF(A29="","",IFERROR(INDEX('جدول الجرد'!$E$2:$E$29,MATCH(A29,'جدول الجرد'!$B$2:$B$29,0)),"")) -> الخرج | D29: 21 | E29: د. علي خليفة | F29: نعم | G29: نعم | H29: =IF(E29="","",IF(AND(F29="نعم",G29="نعم"),"جرد + مراجعة",IF(F29="نعم","جرد فقط",IF(G29="نعم","مراجعة فقط","")))) -> جرد + مراجعة | I29: =IF(H29="جرد + مراجعة",الإعدادات!$B$2,IF(H29="مراجعة فقط",الإعدادات!$B$3,IF(H29="جرد فقط",الإعدادات!$B$4,0))) -> 200
A30: 2026-09-29 | B30: =IF(A30="","",IFERROR(INDEX('جدول الجرد'!$A$2:$A$29,MATCH(A30,'جدول الجرد'!$B$2:$B$29,0)),"")) -> الثلاثاء | C30: =IF(A30="","",IFERROR(INDEX('جدول الجرد'!$E$2:$E$29,MATCH(A30,'جدول الجرد'!$B$2:$B$29,0)),"")) -> الخرج | D30: 21 | E30: د. السيد حسن | G30: نعم | H30: =IF(E30="","",IF(AND(F30="نعم",G30="نعم"),"جرد + مراجعة",IF(F30="نعم","جرد فقط",IF(G30="نعم","مراجعة فقط","")))) -> مراجعة فقط | I30: =IF(H30="جرد + مراجعة",الإعدادات!$B$2,IF(H30="مراجعة فقط",الإعدادات!$B$3,IF(H30="جرد فقط",الإعدادات!$B$4,0))) -> 150
A31: 2026-09-29 | B31: =IF(A31="","",IFERROR(INDEX('جدول الجرد'!$A$2:$A$29,MATCH(A31,'جدول الجرد'!$B$2:$B$29,0)),"")) -> الثلاثاء | C31: =IF(A31="","",IFERROR(INDEX('جدول الجرد'!$E$2:$E$29,MATCH(A31,'جدول الجرد'!$B$2:$B$29,0)),"")) -> الخرج | D31: 21 | E31: د. حسام شلش | G31: نعم | H31: =IF(E31="","",IF(AND(F31="نعم",G31="نعم"),"جرد + مراجعة",IF(F31="نعم","جرد فقط",IF(G31="نعم","مراجعة فقط","")))) -> مراجعة فقط | I31: =IF(H31="جرد + مراجعة",الإعدادات!$B$2,IF(H31="مراجعة فقط",الإعدادات!$B$3,IF(H31="جرد فقط",الإعدادات!$B$4,0))) -> 150
A32: 2026-09-29 | B32: =IF(A32="","",IFERROR(INDEX('جدول الجرد'!$A$2:$A$29,MATCH(A32,'جدول الجرد'!$B$2:$B$29,0)),"")) -> الثلاثاء | C32: =IF(A32="","",IFERROR(INDEX('جدول الجرد'!$E$2:$E$29,MATCH(A32,'جدول الجرد'!$B$2:$B$29,0)),"")) -> الخرج | D32: 21 | E32: د. أيمن حسين | G32: نعم | H32: =IF(E32="","",IF(AND(F32="نعم",G32="نعم"),"جرد + مراجعة",IF(F32="نعم","جرد فقط",IF(G32="نعم","مراجعة فقط","")))) -> مراجعة فقط | I32: =IF(H32="جرد + مراجعة",الإعدادات!$B$2,IF(H32="مراجعة فقط",الإعدادات!$B$3,IF(H32="جرد فقط",الإعدادات!$B$4,0))) -> 150
A33: 2026-09-29 | B33: =IF(A33="","",IFERROR(INDEX('جدول الجرد'!$A$2:$A$29,MATCH(A33,'جدول الجرد'!$B$2:$B$29,0)),"")) -> الثلاثاء | C33: =IF(A33="","",IFERROR(INDEX('جدول الجرد'!$E$2:$E$29,MATCH(A33,'جدول الجرد'!$B$2:$B$29,0)),"")) -> الخرج | D33: 21 | E33: د. الحسن الغنيمي | G33: نعم | H33: =IF(E33="","",IF(AND(F33="نعم",G33="نعم"),"جرد + مراجعة",IF(F33="نعم","جرد فقط",IF(G33="نعم","مراجعة فقط","")))) -> مراجعة فقط | I33: =IF(H33="جرد + مراجعة",الإعدادات!$B$2,IF(H33="مراجعة فقط",الإعدادات!$B$3,IF(H33="جرد فقط",الإعدادات!$B$4,0))) -> 150
A34: 2026-09-29 | B34: =IF(A34="","",IFERROR(INDEX('جدول الجرد'!$A$2:$A$29,MATCH(A34,'جدول الجرد'!$B$2:$B$29,0)),"")) -> الثلاثاء | C34: =IF(A34="","",IFERROR(INDEX('جدول الجرد'!$E$2:$E$29,MATCH(A34,'جدول الجرد'!$B$2:$B$29,0)),"")) -> الخرج | D34: 30 | E34: د. علي خليفة | F34: نعم | G34: نعم | H34: =IF(E34="","",IF(AND(F34="نعم",G34="نعم"),"جرد + مراجعة",IF(F34="نعم","جرد فقط",IF(G34="نعم","مراجعة فقط","")))) -> جرد + مراجعة | I34: =IF(H34="جرد + مراجعة",الإعدادات!$B$2,IF(H34="مراجعة فقط",الإعدادات!$B$3,IF(H34="جرد فقط",الإعدادات!$B$4,0))) -> 200
A35: 2026-09-29 | B35: =IF(A35="","",IFERROR(INDEX('جدول الجرد'!$A$2:$A$29,MATCH(A35,'جدول الجرد'!$B$2:$B$29,0)),"")) -> الثلاثاء | C35: =IF(A35="","",IFERROR(INDEX('جدول الجرد'!$E$2:$E$29,MATCH(A35,'جدول الجرد'!$B$2:$B$29,0)),"")) -> الخرج | D35: 30 | E35: د. السيد حسن | G35: نعم | H35: =IF(E35="","",IF(AND(F35="نعم",G35="نعم"),"جرد + مراجعة",IF(F35="نعم","جرد فقط",IF(G35="نعم","مراجعة فقط","")))) -> مراجعة فقط | I35: =IF(H35="جرد + مراجعة",الإعدادات!$B$2,IF(H35="مراجعة فقط",الإعدادات!$B$3,IF(H35="جرد فقط",الإعدادات!$B$4,0))) -> 150
A36: 2026-09-29 | B36: =IF(A36="","",IFERROR(INDEX('جدول الجرد'!$A$2:$A$29,MATCH(A36,'جدول الجرد'!$B$2:$B$29,0)),"")) -> الثلاثاء | C36: =IF(A36="","",IFERROR(INDEX('جدول الجرد'!$E$2:$E$29,MATCH(A36,'جدول الجرد'!$B$2:$B$29,0)),"")) -> الخرج | D36: 30 | E36: د. حسام شلش | G36: نعم | H36: =IF(E36="","",IF(AND(F36="نعم",G36="نعم"),"جرد + مراجعة",IF(F36="نعم","جرد فقط",IF(G36="نعم","مراجعة فقط","")))) -> مراجعة فقط | I36: =IF(H36="جرد + مراجعة",الإعدادات!$B$2,IF(H36="مراجعة فقط",الإعدادات!$B$3,IF(H36="جرد فقط",الإعدادات!$B$4,0))) -> 150
A37: 2026-09-29 | B37: =IF(A37="","",IFERROR(INDEX('جدول الجرد'!$A$2:$A$29,MATCH(A37,'جدول الجرد'!$B$2:$B$29,0)),"")) -> الثلاثاء | C37: =IF(A37="","",IFERROR(INDEX('جدول الجرد'!$E$2:$E$29,MATCH(A37,'جدول الجرد'!$B$2:$B$29,0)),"")) -> الخرج | D37: 30 | E37: د. أيمن حسين | G37: نعم | H37: =IF(E37="","",IF(AND(F37="نعم",G37="نعم"),"جرد + مراجعة",IF(F37="نعم","جرد فقط",IF(G37="نعم","مراجعة فقط","")))) -> مراجعة فقط | I37: =IF(H37="جرد + مراجعة",الإعدادات!$B$2,IF(H37="مراجعة فقط",الإعدادات!$B$3,IF(H37="جرد فقط",الإعدادات!$B$4,0))) -> 150
A38: 2026-09-29 | B38: =IF(A38="","",IFERROR(INDEX('جدول الجرد'!$A$2:$A$29,MATCH(A38,'جدول الجرد'!$B$2:$B$29,0)),"")) -> الثلاثاء | C38: =IF(A38="","",IFERROR(INDEX('جدول الجرد'!$E$2:$E$29,MATCH(A38,'جدول الجرد'!$B$2:$B$29,0)),"")) -> الخرج | D38: 30 | E38: د. الحسن الغنيمي | G38: نعم | H38: =IF(E38="","",IF(AND(F38="نعم",G38="نعم"),"جرد + مراجعة",IF(F38="نعم","جرد فقط",IF(G38="نعم","مراجعة فقط","")))) -> مراجعة فقط | I38: =IF(H38="جرد + مراجعة",الإعدادات!$B$2,IF(H38="مراجعة فقط",الإعدادات!$B$3,IF(H38="جرد فقط",الإعدادات!$B$4,0))) -> 150
A39: 2026-09-30 | B39: =IF(A39="","",IFERROR(INDEX('جدول الجرد'!$A$2:$A$29,MATCH(A39,'جدول الجرد'!$B$2:$B$29,0)),"")) -> الأربعاء | C39: =IF(A39="","",IFERROR(INDEX('جدول الجرد'!$E$2:$E$29,MATCH(A39,'جدول الجرد'!$B$2:$B$29,0)),"")) -> الخرج | D39: 10 | E39: د. حسام شلش | F39: نعم | G39: نعم | H39: =IF(E39="","",IF(AND(F39="نعم",G39="نعم"),"جرد + مراجعة",IF(F39="نعم","جرد فقط",IF(G39="نعم","مراجعة فقط","")))) -> جرد + مراجعة | I39: =IF(H39="جرد + مراجعة",الإعدادات!$B$2,IF(H39="مراجعة فقط",الإعدادات!$B$3,IF(H39="جرد فقط",الإعدادات!$B$4,0))) -> 200
A40: 2026-09-30 | B40: =IF(A40="","",IFERROR(INDEX('جدول الجرد'!$A$2:$A$29,MATCH(A40,'جدول الجرد'!$B$2:$B$29,0)),"")) -> الأربعاء | C40: =IF(A40="","",IFERROR(INDEX('جدول الجرد'!$E$2:$E$29,MATCH(A40,'جدول الجرد'!$B$2:$B$29,0)),"")) -> الخرج | D40: 10 | E40: د. علي خليفة | G40: نعم | H40: =IF(E40="","",IF(AND(F40="نعم",G40="نعم"),"جرد + مراجعة",IF(F40="نعم","جرد فقط",IF(G40="نعم","مراجعة فقط","")))) -> مراجعة فقط | I40: =IF(H40="جرد + مراجعة",الإعدادات!$B$2,IF(H40="مراجعة فقط",الإعدادات!$B$3,IF(H40="جرد فقط",الإعدادات!$B$4,0))) -> 150
...
